output_dir ./outputs/train_dataset
Map: 100%|████████████████████████████████████████████████████████████████| 60407/60407 [00:08<00:00, 7110.57 examples/s]
Casting the dataset: 100%|███████████████████████████████████████████████| 60407/60407 [00:00<00:00, 93087.21 examples/s]
Traceback (most recent call last):
  File "/opt/conda/lib/python3.10/site-packages/transformers/utils/hub.py", line 403, in cached_file
    resolved_file = hf_hub_download(
  File "/opt/conda/lib/python3.10/site-packages/huggingface_hub/utils/_deprecation.py", line 101, in inner_f
    return f(*args, **kwargs)
  File "/opt/conda/lib/python3.10/site-packages/huggingface_hub/utils/_validators.py", line 106, in _inner_fn
    validate_repo_id(arg_value)
  File "/opt/conda/lib/python3.10/site-packages/huggingface_hub/utils/_validators.py", line 154, in validate_repo_id
    raise HFValidationError(
huggingface_hub.errors.HFValidationError: Repo id must be in the form 'repo_name' or 'namespace/repo_name': './models/train_dataset'. Use `repo_type` argument if needed.

The above exception was the direct cause of the following exception:

Traceback (most recent call last):
  File "/data/ephemeral/home/ksw/level2-mrc-nlp-01/src/main.py", line 533, in <module>
    main()
  File "/data/ephemeral/home/ksw/level2-mrc-nlp-01/src/main.py", line 527, in main
    do_mrc(config, training_args, module_args, logger, is_testing)
  File "/data/ephemeral/home/ksw/level2-mrc-nlp-01/src/main.py", line 180, in do_mrc
    config_hf = AutoConfig.from_pretrained(model_name)
  File "/opt/conda/lib/python3.10/site-packages/transformers/models/auto/configuration_auto.py", line 1006, in from_pretrained
    config_dict, unused_kwargs = PretrainedConfig.get_config_dict(pretrained_model_name_or_path, **kwargs)
  File "/opt/conda/lib/python3.10/site-packages/transformers/configuration_utils.py", line 570, in get_config_dict
    config_dict, kwargs = cls._get_config_dict(pretrained_model_name_or_path, **kwargs)
  File "/opt/conda/lib/python3.10/site-packages/transformers/configuration_utils.py", line 629, in _get_config_dict
    resolved_config_file = cached_file(
  File "/opt/conda/lib/python3.10/site-packages/transformers/utils/hub.py", line 469, in cached_file
    raise EnvironmentError(
OSError: Incorrect path_or_model_id: './models/train_dataset'. Please provide either the path to a local folder or the repo_id of a model on the Hub.
